Workbook
Name ListaAktivnih: Zaposleni!$I$2

Sheet Pravila
A1: Parametar | B1: Vrednost | C1: Opis | E1: Status odsustva | F1: Opis
A2: GO max prenos (dana) | B2: 20 | C2: Maksimalno prenetih dana godišnjeg odmora koji se mogu koristiti u tekućoj godini. | E2: Nacrt | F2: Nije u statistici (samo nacrt/ideja).
A3: Rok za korišćenje prenetog GO | B3: 46203 | C3: Preneti dani (do limita) moraju biti iskorišćeni do 30. juna tekuće godine. | E3: Planirano | F3: Ulazi u 'planirano do kraja godine' (ako je datum u budućnosti).
A4: Tip kod za GO | B4: GO | C4: U tabu Odsustva za godišnji odmor obavezno koristiti Tip (kod) = GO. | E4: Odobreno | F4: Ulazi u statistiku; u budućnosti=planirano, u prošlosti=iskorišćeno.
E5: Evidentirano | F5: Stvarno iskorišćeno (preporučeno za završena odsustva).
A6: Tipovi koji umanjuju GO | B6: vidi Tipovi odsustva! | C6: Kolona 'Umanjuje GO (DA/NE)' određuje koji tipovi odsustva se oduzimaju od godišnjeg. Možeš menjati po potrebi. | E6: Otkazano | F6: Odsustvo je otkazano. (Za automatizaciju: može da obriše događaj iz kalendara / ignoriše u BI.)

Sheet Test Test
A1: Test | B1: Test

Sheet Uputstvo
A1: Odsustva – SBEH | Uputstvo (ažurirano)
A2: Datum ažuriranja: 22.01.2026
A4: Šta je ovaj fajl?
A5: - Jedinstvena evidencija odsustava (GO, bolovanje, neodložni poslovi, itd.) + priprema za automatsku sinhronizaciju sa Outlook/Teams kalendarom (Power Automate).
A7: 1) Gde se unose podaci?
A8: - Tab: Odsustva (tabela: tblOdsustva). Popunjavate red po red.
A9: - Obavezna polja u redu: Zaposleni, Tip (kod), Datum od, Datum do, Status.
A10: - Napomena je opcionalna (korisno za opis / razlog).
A12: 2) Statusi (kolona: Status)
A13: - Planirano: zahtev je u planu (može da se menja).
A14: - Odobreno: menadžment/HR odobrio.
A15: - Evidentirano: odsustvo je već realizovano (nakon što prođe).
... A41: - Ako formule ne 'povuku' odmah, osvežite fajl (Refresh) ili kopirajte formule u nove redove (Excel ponekad ne primeni automatski u tabeli).

Sheet Zaposleni
A1: ID | B1: Ime i prezime | C1: Tim | D1: Datum zaposlenja | E1: Status | F1: Aktivan? | G1: GO preneto (dana) | H1: GO kvota godišnje (dana) | I1: Liste
A2: 1 | B2: Milica Milisavljević | C2: legal | D2: 44621 | E2: Aktivan | F2: =IF($E2="Aktivan",1,0) -> 1 | G2: 18 | H2: 20 | I2: {=_xlfn._xlws.SORT(_xlfn._xlws.FILTER(Zaposleni!$B$2:$B$200, Zaposleni!$E$2:$E$200="Aktivan"))} -> Aleksandar Janković
A3: 2 | B3: Nikola Lazarević | C3: tech | D3: 44362 | E3: Aktivan | F3: =IF($E3="Aktivan",1,0) -> 1 | G3: 13 | H3: 20 | I3: Dejan Đorić
A4: 3 | B4: Luka Pandurov | C4: tech | D4: 44109 | E4: Aktivan | F4: =IF($E4="Aktivan",1,0) -> 1 | G4: 15 | H4: 20 | I4: Dragan Babić
A5: 4 | B5: Stefan Josimov | C5: field ops | D5: 44936 | E5: Aktivan | F5: =IF($E5="Aktivan",1,0) -> 1 | G5: 13 | H5: 20 | I5: Ivana Rosić
A6: 5 | B6: Slavko Marjanović | C6: tech | D6: 43710 | E6: Aktivan | F6: =IF($E6="Aktivan",1,0) -> 1 | G6: 16 | H6: 20 | I6: Luka Kostov Drndarski
A7: 6 | B7: Dejan Đorić | C7: legal | D7: 44872 | E7: Aktivan | F7: =IF($E7="Aktivan",1,0) -> 1 | G7: 14 | H7: 20 | I7: Luka Pandurov
A8: 7 | B8: Stevo Ljubičić | C8: field ops | D8: 45323 | E8: Aktivan | F8: =IF($E8="Aktivan",1,0) -> 1 | G8: 6 | H8: 20 | I8: Maja Petrović
A9: 8 | B9: Ivana Rosić | C9: admin | D9: 43941 | E9: Aktivan | F9: =IF($E9="Aktivan",1,0) -> 1 | G9: 7 | H9: 20 | I9: Mihailo Savić
A10: 9 | B10: Maja Petrović | C10: legal | D10: 43297 | E10: Aktivan | F10: =IF($E10="Aktivan",1,0) -> 1 | G10: 16 | H10: 20 | I10: Milica Milisavljević
A11: 10 | B11: Ružica Pantović | C11: finance | D11: 44221 | E11: Aktivan | F11: =IF($E11="Aktivan",1,0) -> 1 | G11: 16 | H11: 20 | I11: Mina Simonović
A12: 11 | B12: Mihailo Savić | C12: tech | D12: 42863 | E12: Aktivan | F12: =IF($E12="Aktivan",1,0) -> 1 | G12: 10 | H12: 20 | I12: Nikola Lazarević
A13: 12 | B13: Uroš Velinovski | C13: tech | D13: 43510 | E13: Aktivan | F13: =IF($E13="Aktivan",1,0) -> 1 | G13: 14 | H13: 20 | I13: Olga Jovanović
A14: 13 | B14: Mina Simonović | C14: legal | D14: 45173 | E14: Aktivan | F14: =IF($E14="Aktivan",1,0) -> 1 | G14: 5 | H14: 20 | I14: Ružica Pantović
... A17: 16 | B17: Aleksandar Janković | C17: Operacije | D17: 44791 | E17: Aktivan | F17: =IF($E17="Aktivan",1,0) -> 1 | G17: 2 | H17: 20 | I17: Stevo Ljubičić
A18: 17 | B18: Luka Kostov Drndarski | C18: direktor | E18: Aktivan | F18: =IF($E18="Aktivan",1,0) -> 1 | G18: 10 | H18: 20 | I18: Uroš Velinovski
F19: =IF($E19="Aktivan",1,0) -> 0
F20: =IF($E20="Aktivan",1,0) -> 0
F21: =IF($E21="Aktivan",1,0) -> 0
F22: =IF($E22="Aktivan",1,0) -> 0
F23: =IF($E23="Aktivan",1,0) -> 0
F24: =IF($E24="Aktivan",1,0) -> 0

Sheet Tipovi odsustva
A1: Kod | B1: Tip odsustva | C1: Opis | D1: Umanjuje GO (DA/NE)
A2: BO | B2: Bolovanje | C2: Zdravstveno odsustvo (uz doznake po potrebi) | D2: NE
A3: GO | B3: Godišnji odmor | C3: Planirani godišnji odmor | D3: DA
A4: FA | B4: Fakultet | C4: Obaveze vezane za studije/ispite | D4: DA/NE
A5: NP | B5: Neodložni poslovi | C5: Hitne privatne obaveze | D5: DA/NE
A6: OS | B6: Ostalo | C6: Sve ostalo (navesti u napomeni) | D6: DA/NE
A7: SV | B7: Slava/verski praznik | C7: Odsustvo zbog slave ili verskog praznika | D7: NE

Sheet Praznici
A1: Datum | B1: Naziv praznika / neradnog dana
A2: 46023 | B2: Nova Godina
A3: 46024 | B3: Nova Godina
A4: 46029 | B4: Božić (Pravoslavni)
A5: 46068 | B5: Dan državnosti
A6: 46069 | B6: Dan državnosti
A7: 46070 | B7: Dan državnosti
A8: 46122 | B8: Uskrs (Pravoslavni)
A9: 46123 | B9: Uskrs (Pravoslavni)
A10: 46124 | B10: Uskrs (Pravoslavni)
A11: 46125 | B11: Uskrs (Pravoslavni)
A12: 46143 | B12: Praznik rada
A13: 46144 | B13: Praznik rada
A14: 46337 | B14: Dan primirja u I svetskom ratu

Sheet Odsustva
A1: ID | B1: Zaposleni | C1: Tip (kod) | D1: Datum od | E1: Datum do | F1: Broj dana (radni) | G1: Godina | H1: Mesec | I1: Napomena | J1: Status | K1: Umanjuje GO | L1: CalendarEventID | M1: SyncStatus | N1: LastSyncedOn | O1: LastSyncMessage
A2: =ROW() - ROW(tblOdsustva[[#Headers],[ID]]) -> 1 | B2: Uroš Velinovski | C2: NP | D2: 46035 | E2: 46035 | F2: =IF(AND(D2<>"",E2<>""),NETWORKDAYS.INTL(D2,E2,1,Praznici!$A$2:$A$200),"") -> 1 | G2: =IF(D2<>"",YEAR(D2),"") -> 2026 | H2: =IF(D2<>"",MONTH(D2),"") -> 1 | I2: neodlozni poslovi | J2: Evidentirano | K2: DA | L2: AAMkADIwYmIwZjI4LWI5NGYtNDMwYy1hMjM3LTAyNWYwNDU5MTYzNwBGAAAAAABCyJptxNOoQIA24H_7GwlXBwBG8Zz3r_PMT7RDuJzmmKnJAAAAAAENAABG8Zz3r_PMT7RDuJzmmKnJAAAnStSQAAA= | M2: CREATED | N2: 2026-01-21T10:43:50.8442552Z
A3: =ROW() - ROW(tblOdsustva[[#Headers],[ID]]) -> 2 | B3: Uroš Velinovski | C3: NP | D3: 46037 | E3: 46037 | F3: =IF(AND(D3<>"",E3<>""),NETWORKDAYS.INTL(D3,E3,1,Praznici!$A$2:$A$200),"") -> 1 | G3: =IF(D3<>"",YEAR(D3),"") -> 2026 | H3: =IF(D3<>"",MONTH(D3),"") -> 1 | I3: neodlozni poslovi | J3: Evidentirano | K3: DA | L3: AAMkADIwYmIwZjI4LWI5NGYtNDMwYy1hMjM3LTAyNWYwNDU5MTYzNwBGAAAAAABCyJptxNOoQIA24H_7GwlXBwBG8Zz3r_PMT7RDuJzmmKnJAAAAAAENAABG8Zz3r_PMT7RDuJzmmKnJAAAnStSSAAA= | M3: CREATED | N3: 2026-01-21T10:43:52.5256147Z
A4: =ROW() - ROW(tblOdsustva[[#Headers],[ID]]) -> 3 | B4: Mina Simonović | C4: FA | D4: 46042 | E4: 46042 | F4: =IF(AND(D4<>"",E4<>""),NETWORKDAYS.INTL(D4,E4,1,Praznici!$A$2:$A$200),"") -> 1 | G4: =IF(D4<>"",YEAR(D4),"") -> 2026 | H4: =IF(D4<>"",MONTH(D4),"") -> 1 | I4: Ispit | J4: Evidentirano | K4: NE | L4: AAMkADIwYmIwZjI4LWI5NGYtNDMwYy1hMjM3LTAyNWYwNDU5MTYzNwBGAAAAAABCyJptxNOoQIA24H_7GwlXBwBG8Zz3r_PMT7RDuJzmmKnJAAAAAAENAABG8Zz3r_PMT7RDuJzmmKnJAAAnStSUAAA= | M4: CREATED | N4: 2026-01-21T10:43:53.7270364Z
A5: =ROW() - ROW(tblOdsustva[[#Headers],[ID]]) -> 4 | B5: Stevo Ljubičić | C5: GO | D5: 46191 | E5: 46196 | F5: =IF(AND(D5<>"",E5<>""),NETWORKDAYS.INTL(D5,E5,1,Praznici!$A$2:$A$200),"") -> 4 | G5: =IF(D5<>"",YEAR(D5),"") -> 2026 | H5: =IF(D5<>"",MONTH(D5),"") -> 6 | I5: Odmor | J5: Odobreno | K5: DA | L5: AAMkADIwYmIwZjI4LWI5NGYtNDMwYy1hMjM3LTAyNWYwNDU5MTYzNwBGAAAAAABCyJptxNOoQIA24H_7GwlXBwBG8Zz3r_PMT7RDuJzmmKnJAAAAAAENAABG8Zz3r_PMT7RDuJzmmKnJAAAnStSWAAA= | M5: CREATED | N5: 2026-01-21T10:43:55.1446021Z
A6: =ROW() - ROW(tblOdsustva[[#Headers],[ID]]) -> 5 | B6: Luka Pandurov | C6: GO | D6: 46055 | E6: 46059 | F6: =IF(AND(D6<>"",E6<>""),NETWORKDAYS.INTL(D6,E6,1,Praznici!$A$2:$A$200),"") -> 5 | G6: =IF(D6<>"",YEAR(D6),"") -> 2026 | H6: =IF(D6<>"",MONTH(D6),"") -> 2 | I6: Odmor | J6: Odobreno | K6: DA | L6: AAMkADIwYmIwZjI4LWI5NGYtNDMwYy1hMjM3LTAyNWYwNDU5MTYzNwBGAAAAAABCyJptxNOoQIA24H_7GwlXBwBG8Zz3r_PMT7RDuJzmmKnJAAAAAAENAABG8Zz3r_PMT7RDuJzmmKnJAAAnStSYAAA= | M6: CREATED | N6: 2026-01-21T10:43:56.9333994Z
A7: =ROW() - ROW(tblOdsustva[[#Headers],[ID]]) -> 6 | B7: Aleksandar Janković | C7: NP | D7: 46050 | E7: 46062 | F7: =IF(AND(D7<>"",E7<>""),NETWORKDAYS.INTL(D7,E7,1,Praznici!$A$2:$A$200),"") -> 9 | G7: =IF(D7<>"",YEAR(D7),"") -> 2026 | H7: =IF(D7<>"",MONTH(D7),"") -> 1 | I7: Test test | J7: Otkazano | K7: NE | L7: AAMkADIwYmIwZjI4LWI5NGYtNDMwYy1hMjM3LTAyNWYwNDU5MTYzNwBGAAAAAABCyJptxNOoQIA24H_7GwlXBwBG8Zz3r_PMT7RDuJzmmKnJAAAAAAENAABG8Zz3r_PMT7RDuJzmmKnJAAAnStSkAAA= | M7: DELETED | N7: 2026-01-21T12:00:09.0796879Z
A8: =ROW() - ROW(tblOdsustva[[#Headers],[ID]]) -> 7 | B8: Slavko Marjanović | C8: GO | D8: 46064 | E8: 46071 | F8: =IF(AND(D8<>"",E8<>""),NETWORKDAYS.INTL(D8,E8,1,Praznici!$A$2:$A$200),"") -> 4 | G8: =IF(D8<>"",YEAR(D8),"") -> 2026 | H8: =IF(D8<>"",MONTH(D8),"") -> 2 | I8: Slavko ide na odmor | J8: Odobreno | K8: DA | L8: AAMkADIwYmIwZjI4LWI5NGYtNDMwYy1hMjM3LTAyNWYwNDU5MTYzNwBGAAAAAABCyJptxNOoQIA24H_7GwlXBwBG8Zz3r_PMT7RDuJzmmKnJAAAAAAENAABG8Zz3r_PMT7RDuJzmmKnJAAAnStSeAAA= | M8: CREATED | N8: 2026-01-21T10:47:57.0604554Z
A9: =ROW() - ROW(tblOdsustva[[#Headers],[ID]]) -> 8 | B9: Stevo Ljubičić | C9: NP | D9: 46072 | E9: 46073 | F9: =IF(AND(D9<>"",E9<>""),NETWORKDAYS.INTL(D9,E9,1,Praznici!$A$2:$A$200),"") -> 2 | G9: =IF(D9<>"",YEAR(D9),"") -> 2026 | H9: =IF(D9<>"",MONTH(D9),"") -> 2 | I9: Pasoš | J9: Odobreno | K9: DA | L9: AAMkADIwYmIwZjI4LWI5NGYtNDMwYy1hMjM3LTAyNWYwNDU5MTYzNwBGAAAAAABCyJptxNOoQIA24H_7GwlXBwBG8Zz3r_PMT7RDuJzmmKnJAAAAAAENAABG8Zz3r_PMT7RDuJzmmKnJAAAnStSiAAA= | M9: CREATED | N9: 2026-01-21T11:09:37.1826015Z
A10: =ROW() - ROW(tblOdsustva[[#Headers],[ID]]) -> 9 | B10: Dragan Babić | C10: NP | D10: 46072 | E10: 46079 | F10: =IF(AND(D10<>"",E10<>""),NETWORKDAYS.INTL(D10,E10,1,Praznici!$A$2:$A$200),"") -> 6 | G10: =IF(D10<>"",YEAR(D10),"") -> 2026 | H10: =IF(D10<>"",MONTH(D10),"") -> 2
A11: =ROW() - ROW(tblOdsustva[[#Headers],[ID]]) -> 10 | F11: =IF(AND(D11<>"",E11<>""),NETWORKDAYS.INTL(D11,E11,1,Praznici!$A$2:$A$200),"") | G11: =IF(D11<>"",YEAR(D11),"") | H11: =IF(D11<>"",MONTH(D11),"")
A12: =ROW() - ROW(tblOdsustva[[#Headers],[ID]]) -> 11 | F12: =IF(AND(D12<>"",E12<>""),NETWORKDAYS.INTL(D12,E12,1,Praznici!$A$2:$A$200),"") | G12: =IF(D12<>"",YEAR(D12),"") | H12: =IF(D12<>"",MONTH(D12),"")
A13: =ROW() - ROW(tblOdsustva[[#Headers],[ID]]) -> 12 | F13: =IF(AND(D13<>"",E13<>""),NETWORKDAYS.INTL(D13,E13,1,Praznici!$A$2:$A$200),"") | G13: =IF(D13<>"",YEAR(D13),"") | H13: =IF(D13<>"",MONTH(D13),"")
A14: =ROW() - ROW(tblOdsustva[[#Headers],[ID]]) -> 13 | F14: =IF(AND(D14<>"",E14<>""),NETWORKDAYS.INTL(D14,E14,1,Praznici!$A$2:$A$200),"") | G14: =IF(D14<>"",YEAR(D14),"") | H14: =IF(D14<>"",MONTH(D14),"")
A15: =ROW() - ROW(tblOdsustva[[#Headers],[ID]]) -> 14 | F15: =IF(AND(D15<>"",E15<>""),NETWORKDAYS.INTL(D15,E15,1,Praznici!$A$2:$A$200),"") | G15: =IF(D15<>"",YEAR(D15),"") | H15: =IF(D15<>"",MONTH(D15),"")
A16: =ROW() - ROW(tblOdsustva[[#Headers],[ID]]) -> 15 | F16: =IF(AND(D16<>"",E16<>""),NETWORKDAYS.INTL(D16,E16,1,Praznici!$A$2:$A$200),"") | G16: =IF(D16<>"",YEAR(D16),"") | H16: =IF(D16<>"",MONTH(D16),"")
A17: =ROW() - ROW(tblOdsustva[[#Headers],[ID]]) -> 16 | F17: =IF(AND(D17<>"",E17<>""),NETWORKDAYS.INTL(D17,E17,1,Praznici!$A$2:$A$200),"") | G17: =IF(D17<>"",YEAR(D17),"") | H17: =IF(D17<>"",MONTH(D17),"")
A18: =ROW() - ROW(tblOdsustva[[#Headers],[ID]]) -> 17 | F18: =IF(AND(D18<>"",E18<>""),NETWORKDAYS.INTL(D18,E18,1,Praznici!$A$2:$A$200),"") | G18: =IF(D18<>"",YEAR(D18),"") | H18: =IF(D18<>"",MONTH(D18),"")
A19: =ROW() - ROW(tblOdsustva[[#Headers],[ID]]) -> 18 | F19: =IF(AND(D19<>"",E19<>""),NETWORKDAYS.INTL(D19,E19,1,Praznici!$A$2:$A$200),"") | G19: =IF(D19<>"",YEAR(D19),"") | H19: =IF(D19<>"",MONTH(D19),"")
A20: =ROW() - ROW(tblOdsustva[[#Headers],[ID]]) -> 19 | F20: =IF(AND(D20<>"",E20<>""),NETWORKDAYS.INTL(D20,E20,1,Praznici!$A$2:$A$200),"") | G20: =IF(D20<>"",YEAR(D20),"") | H20: =IF(D20<>"",MONTH(D20),"")
A21: =ROW() - ROW(tblOdsustva[[#Headers],[ID]]) -> 20 | F21: =IF(AND(D21<>"",E21<>""),NETWORKDAYS.INTL(D21,E21,1,Praznici!$A$2:$A$200),"") | G21: =IF(D21<>"",YEAR(D21),"") | H21: =IF(D21<>"",MONTH(D21),"")
A22: =ROW() - ROW(tblOdsustva[[#Headers],[ID]]) -> 21 | F22: =IF(AND(D22<>"",E22<>""),NETWORKDAYS.INTL(D22,E22,1,Praznici!$A$2:$A$200),"") | G22: =IF(D22<>"",YEAR(D22),"") | H22: =IF(D22<>"",MONTH(D22),"")
... A48: =ROW() - ROW(tblOdsustva[[#Headers],[ID]]) -> 47 | F48: =IF(AND(D48<>"",E48<>""),NETWORKDAYS.INTL(D48,E48,1,Praznici!$A$2:$A$200),"") | G48: =IF(D48<>"",YEAR(D48),"") | H48: =IF(D48<>"",MONTH(D48),"")
A49: =ROW() - ROW(tblOdsustva[[#Headers],[ID]]) -> 48 | F49: =IF(AND(D49<>"",E49<>""),NETWORKDAYS.INTL(D49,E49,1,Praznici!$A$2:$A$200),"") | H49: =IF(D49<>"",MONTH(D49),"")
A50: =ROW() - ROW(tblOdsustva[[#Headers],[ID]]) -> 49 | F50: =IF(AND(D50<>"",E50<>""),NETWORKDAYS.INTL(D50,E50,1,Praznici!$A$2:$A$200),"") | H50: =IF(D50<>"",MONTH(D50),"")
A51: =ROW() - ROW(tblOdsustva[[#Headers],[ID]]) -> 50 | F51: =IF(AND(D51<>"",E51<>""),NETWORKDAYS.INTL(D51,E51,1,Praznici!$A$2:$A$200),"") | H51: =IF(D51<>"",MONTH(D51),"")
A52: =ROW() - ROW(tblOdsustva[[#Headers],[ID]]) -> 51 | F52: =IF(AND(D52<>"",E52<>""),NETWORKDAYS.INTL(D52,E52,1,Praznici!$A$2:$A$200),"") | H52: =IF(D52<>"",MONTH(D52),"")
A53: =ROW() - ROW(tblOdsustva[[#Headers],[ID]]) -> 52 | F53: =IF(AND(D53<>"",E53<>""),NETWORKDAYS.INTL(D53,E53,1,Praznici!$A$2:$A$200),"") | H53: =IF(D53<>"",MONTH(D53),"")
A54: =ROW() - ROW(tblOdsustva[[#Headers],[ID]]) -> 53 | F54: =IF(AND(D54<>"",E54<>""),NETWORKDAYS.INTL(D54,E54,1,Praznici!$A$2:$A$200),"") | H54: =IF(D54<>"",MONTH(D54),"")
A55: =ROW() - ROW(tblOdsustva[[#Headers],[ID]]) -> 54 | F55: =IF(AND(D55<>"",E55<>""),NETWORKDAYS.INTL(D55,E55,1,Praznici!$A$2:$A$200),"") | H55: =IF(D55<>"",MONTH(D55),"")
A56: =ROW() - ROW(tblOdsustva[[#Headers],[ID]]) -> 55 | F56: =IF(AND(D56<>"",E56<>""),NETWORKDAYS.INTL(D56,E56,1,Praznici!$A$2:$A$200),"") | H56: =IF(D56<>"",MONTH(D56),"")
A57: =ROW() - ROW(tblOdsustva[[#Headers],[ID]]) -> 56 | F57: =IF(AND(D57<>"",E57<>""),NETWORKDAYS.INTL(D57,E57,1,Praznici!$A$2:$A$200),"") | H57: =IF(D57<>"",MONTH(D57),"")
A58: =ROW() - ROW(tblOdsustva[[#Headers],[ID]]) -> 57 | F58: =IF(AND(D58<>"",E58<>""),NETWORKDAYS.INTL(D58,E58,1,Praznici!$A$2:$A$200),"") | H58: =IF(D58<>"",MONTH(D58),"")
A59: =ROW() - ROW(tblOdsustva[[#Headers],[ID]]) -> 58 | F59: =IF(AND(D59<>"",E59<>""),NETWORKDAYS.INTL(D59,E59,1,Praznici!$A$2:$A$200),"") | H59: =IF(D59<>"",MONTH(D59),"")
A60: =ROW() - ROW(tblOdsustva[[#Headers],[ID]]) -> 59 | F60: =IF(AND(D60<>"",E60<>""),NETWORKDAYS.INTL(D60,E60,1,Praznici!$A$2:$A$200),"") | H60: =IF(D60<>"",MONTH(D60),"")
... A66: =ROW() - ROW(tblOdsustva[[#Headers],[ID]]) -> 65 | F66: =IF(AND(D66<>"",E66<>""),NETWORKDAYS.INTL(D66,E66,1,Praznici!$A$2:$A$200),"") | H66: =IF(D66<>"",MONTH(D66),"")
A67: =ROW() - ROW(tblOdsustva[[#Headers],[ID]]) -> 66 | F67: =IF(AND(D67<>"",E67<>""),NETWORKDAYS.INTL(D67,E67,1,Praznici!$A$2:$A$200),"")
A68: =ROW() - ROW(tblOdsustva[[#Headers],[ID]]) -> 67 | F68: =IF(AND(D68<>"",E68<>""),NETWORKDAYS.INTL(D68,E68,1,Praznici!$A$2:$A$200),"")
A69: =ROW() - ROW(tblOdsustva[[#Headers],[ID]]) -> 68 | F69: =IF(AND(D69<>"",E69<>""),NETWORKDAYS.INTL(D69,E69,1,Praznici!$A$2:$A$200),"")
A70: =ROW() - ROW(tblOdsustva[[#Headers],[ID]]) -> 69 | F70: =IF(AND(D70<>"",E70<>""),NETWORKDAYS.INTL(D70,E70,1,Praznici!$A$2:$A$200),"")
...

Sheet Statistika
A1: Statistika odsustava
A3: Izabrana godina: | B3: 2026
A5: Po zaposlenom (zbir Broj dana (radni)):
A6: Zaposleni | B6: BO (Bolovanje) | C6: GO (Godišnji) | D6: FA (Fakultet) | E6: NP (Neodložni) | F6: OS (Ostalo) | G6: SV (Slava/verski) | H6: Ukupno
A7: Milica Milisavljević | B7: =SUMIFS(Odsustva!$F$2:$F$500,Odsustva!$B$2:$B$500,$A7,Odsustva!$C$2:$C$500,"BO",Odsustva!$G$2:$G$500,$B$3,Odsustva!$J$2:$J$500,"<>Otkazano") -> 0 | C7: =SUMIFS(Odsustva!$F$2:$F$500,Odsustva!$B$2:$B$500,$A7,Odsustva!$C$2:$C$500,"GO",Odsustva!$G$2:$G$500,$B$3,Odsustva!$J$2:$J$500,"<>Otkazano") -> 0 | D7: =SUMIFS(Odsustva!$F$2:$F$500,Odsustva!$B$2:$B$500,$A7,Odsustva!$C$2:$C$500,"FA",Odsustva!$G$2:$G$500,$B$3,Odsustva!$J$2:$J$500,"<>Otkazano") -> 0 | E7: =SUMIFS(Odsustva!$F$2:$F$500,Odsustva!$B$2:$B$500,$A7,Odsustva!$C$2:$C$500,"NP",Odsustva!$G$2:$G$500,$B$3,Odsustva!$J$2:$J$500,"<>Otkazano") -> 0 | F7: =SUMIFS(Odsustva!$F$2:$F$500,Odsustva!$B$2:$B$500,$A7,Odsustva!$C$2:$C$500,"OS",Odsustva!$G$2:$G$500,$B$3,Odsustva!$J$2:$J$500,"<>Otkazano") -> 0 | G7: =SUMIFS(Odsustva!$F$2:$F$500,Odsustva!$B$2:$B$500,$A7,Odsustva!$C$2:$C$500,"SV",Odsustva!$G$2:$G$500,$B$3,Odsustva!$J$2:$J$500,"<>Otkazano") -> 0 | H7: =SUM(B7:G7) -> 0
A8: Nikola Lazarević | B8: =SUMIFS(Odsustva!$F$2:$F$500,Odsustva!$B$2:$B$500,$A8,Odsustva!$C$2:$C$500,"BO",Odsustva!$G$2:$G$500,$B$3,Odsustva!$J$2:$J$500,"<>Otkazano") -> 0 | C8: =SUMIFS(Odsustva!$F$2:$F$500,Odsustva!$B$2:$B$500,$A8,Odsustva!$C$2:$C$500,"GO",Odsustva!$G$2:$G$500,$B$3,Odsustva!$J$2:$J$500,"<>Otkazano") -> 0 | D8: =SUMIFS(Odsustva!$F$2:$F$500,Odsustva!$B$2:$B$500,$A8,Odsustva!$C$2:$C$500,"FA",Odsustva!$G$2:$G$500,$B$3,Odsustva!$J$2:$J$500,"<>Otkazano") -> 0 | E8: =SUMIFS(Odsustva!$F$2:$F$500,Odsustva!$B$2:$B$500,$A8,Odsustva!$C$2:$C$500,"NP",Odsustva!$G$2:$G$500,$B$3,Odsustva!$J$2:$J$500,"<>Otkazano") -> 0 | F8: =SUMIFS(Odsustva!$F$2:$F$500,Odsustva!$B$2:$B$500,$A8,Odsustva!$C$2:$C$500,"OS",Odsustva!$G$2:$G$500,$B$3,Odsustva!$J$2:$J$500,"<>Otkazano") -> 0 | G8: =SUMIFS(Odsustva!$F$2:$F$500,Odsustva!$B$2:$B$500,$A8,Odsustva!$C$2:$C$500,"SV",Odsustva!$G$2:$G$500,$B$3,Odsustva!$J$2:$J$500,"<>Otkazano") -> 0 | H8: =SUM(B8:G8) -> 0
A9: Luka Pandurov | B9: =SUMIFS(Odsustva!$F$2:$F$500,Odsustva!$B$2:$B$500,$A9,Odsustva!$C$2:$C$500,"BO",Odsustva!$G$2:$G$500,$B$3,Odsustva!$J$2:$J$500,"<>Otkazano") -> 0 | C9: =SUMIFS(Odsustva!$F$2:$F$500,Odsustva!$B$2:$B$500,$A9,Odsustva!$C$2:$C$500,"GO",Odsustva!$G$2:$G$500,$B$3,Odsustva!$J$2:$J$500,"<>Otkazano") -> 5 | D9: =SUMIFS(Odsustva!$F$2:$F$500,Odsustva!$B$2:$B$500,$A9,Odsustva!$C$2:$C$500,"FA",Odsustva!$G$2:$G$500,$B$3,Odsustva!$J$2:$J$500,"<>Otkazano") -> 0 | E9: =SUMIFS(Odsustva!$F$2:$F$500,Odsustva!$B$2:$B$500,$A9,Odsustva!$C$2:$C$500,"NP",Odsustva!$G$2:$G$500,$B$3,Odsustva!$J$2:$J$500,"<>Otkazano") -> 0 | F9: =SUMIFS(Odsustva!$F$2:$F$500,Odsustva!$B$2:$B$500,$A9,Odsustva!$C$2:$C$500,"OS",Odsustva!$G$2:$G$500,$B$3,Odsustva!$J$2:$J$500,"<>Otkazano") -> 0 | G9: =SUMIFS(Odsustva!$F$2:$F$500,Odsustva!$B$2:$B$500,$A9,Odsustva!$C$2:$C$500,"SV",Odsustva!$G$2:$G$500,$B$3,Odsustva!$J$2:$J$500,"<>Otkazano") -> 0 | H9: =SUM(B9:G9) -> 5
A10: Stefan Josimov | B10: =SUMIFS(Odsustva!$F$2:$F$500,Odsustva!$B$2:$B$500,$A10,Odsustva!$C$2:$C$500,"BO",Odsustva!$G$2:$G$500,$B$3,Odsustva!$J$2:$J$500,"<>Otkazano") -> 0 | C10: =SUMIFS(Odsustva!$F$2:$F$500,Odsustva!$B$2:$B$500,$A10,Odsustva!$C$2:$C$500,"GO",Odsustva!$G$2:$G$500,$B$3,Odsustva!$J$2:$J$500,"<>Otkazano") -> 0 | D10: =SUMIFS(Odsustva!$F$2:$F$500,Odsustva!$B$2:$B$500,$A10,Odsustva!$C$2:$C$500,"FA",Odsustva!$G$2:$G$500,$B$3,Odsustva!$J$2:$J$500,"<>Otkazano") -> 0 | E10: =SUMIFS(Odsustva!$F$2:$F$500,Odsustva!$B$2:$B$500,$A10,Odsustva!$C$2:$C$500,"NP",Odsustva!$G$2:$G$500,$B$3,Odsustva!$J$2:$J$500,"<>Otkazano") -> 0 | F10: =SUMIFS(Odsustva!$F$2:$F$500,Odsustva!$B$2:$B$500,$A10,Odsustva!$C$2:$C$500,"OS",Odsustva!$G$2:$G$500,$B$3,Odsustva!$J$2:$J$500,"<>Otkazano") -> 0 | G10: =SUMIFS(Odsustva!$F$2:$F$500,Odsustva!$B$2:$B$500,$A10,Odsustva!$C$2:$C$500,"SV",Odsustva!$G$2:$G$500,$B$3,Odsustva!$J$2:$J$500,"<>Otkazano") -> 0 | H10: =SUM(B10:G10) -> 0
A11: Slavko Marjanović | B11: =SUMIFS(Odsustva!$F$2:$F$500,Odsustva!$B$2:$B$500,$A11,Odsustva!$C$2:$C$500,"BO",Odsustva!$G$2:$G$500,$B$3,Odsustva!$J$2:$J$500,"<>Otkazano") -> 0 | C11: =SUMIFS(Odsustva!$F$2:$F$500,Odsustva!$B$2:$B$500,$A11,Odsustva!$C$2:$C$500,"GO",Odsustva!$G$2:$G$500,$B$3,Odsustva!$J$2:$J$500,"<>Otkazano") -> 4 | D11: =SUMIFS(Odsustva!$F$2:$F$500,Odsustva!$B$2:$B$500,$A11,Odsustva!$C$2:$C$500,"FA",Odsustva!$G$2:$G$500,$B$3,Odsustva!$J$2:$J$500,"<>Otkazano") -> 0 | E11: =SUMIFS(Odsustva!$F$2:$F$500,Odsustva!$B$2:$B$500,$A11,Odsustva!$C$2:$C$500,"NP",Odsustva!$G$2:$G$500,$B$3,Odsustva!$J$2:$J$500,"<>Otkazano") -> 0 | F11: =SUMIFS(Odsustva!$F$2:$F$500,Odsustva!$B$2:$B$500,$A11,Odsustva!$C$2:$C$500,"OS",Odsustva!$G$2:$G$500,$B$3,Odsustva!$J$2:$J$500,"<>Otkazano") -> 0 | G11: =SUMIFS(Odsustva!$F$2:$F$500,Odsustva!$B$2:$B$500,$A11,Odsustva!$C$2:$C$500,"SV",Odsustva!$G$2:$G$500,$B$3,Odsustva!$J$2:$J$500,"<>Otkazano") -> 0 | H11: =SUM(B11:G11) -> 4
A12: Dejan Đorić | B12: =SUMIFS(Odsustva!$F$2:$F$500,Odsustva!$B$2:$B$500,$A12,Odsustva!$C$2:$C$500,"BO",Odsustva!$G$2:$G$500,$B$3,Odsustva!$J$2:$J$500,"<>Otkazano") -> 0 | C12: =SUMIFS(Odsustva!$F$2:$F$500,Odsustva!$B$2:$B$500,$A12,Odsustva!$C$2:$C$500,"GO",Odsustva!$G$2:$G$500,$B$3,Odsustva!$J$2:$J$500,"<>Otkazano") -> 0 | D12: =SUMIFS(Odsustva!$F$2:$F$500,Odsustva!$B$2:$B$500,$A12,Odsustva!$C$2:$C$500,"FA",Odsustva!$G$2:$G$500,$B$3,Odsustva!$J$2:$J$500,"<>Otkazano") -> 0 | E12: =SUMIFS(Odsustva!$F$2:$F$500,Odsustva!$B$2:$B$500,$A12,Odsustva!$C$2:$C$500,"NP",Odsustva!$G$2:$G$500,$B$3,Odsustva!$J$2:$J$500,"<>Otkazano") -> 0 | F12: =SUMIFS(Odsustva!$F$2:$F$500,Odsustva!$B$2:$B$500,$A12,Odsustva!$C$2:$C$500,"OS",Odsustva!$G$2:$G$500,$B$3,Odsustva!$J$2:$J$500,"<>Otkazano") -> 0 | G12: =SUMIFS(Odsustva!$F$2:$F$500,Odsustva!$B$2:$B$500,$A12,Odsustva!$C$2:$C$500,"SV",Odsustva!$G$2:$G$500,$B$3,Odsustva!$J$2:$J$500,"<>Otkazano") -> 0 | H12: =SUM(B12:G12) -> 0
A13: Stevo Ljubičić | B13: =SUMIFS(Odsustva!$F$2:$F$500,Odsustva!$B$2:$B$500,$A13,Odsustva!$C$2:$C$500,"BO",Odsustva!$G$2:$G$500,$B$3,Odsustva!$J$2:$J$500,"<>Otkazano") -> 0 | C13: =SUMIFS(Odsustva!$F$2:$F$500,Odsustva!$B$2:$B$500,$A13,Odsustva!$C$2:$C$500,"GO",Odsustva!$G$2:$G$500,$B$3,Odsustva!$J$2:$J$500,"<>Otkazano") -> 4 | D13: =SUMIFS(Odsustva!$F$2:$F$500,Odsustva!$B$2:$B$500,$A13,Odsustva!$C$2:$C$500,"FA",Odsustva!$G$2:$G$500,$B$3,Odsustva!$J$2:$J$500,"<>Otkazano") -> 0 | E13: =SUMIFS(Odsustva!$F$2:$F$500,Odsustva!$B$2:$B$500,$A13,Odsustva!$C$2:$C$500,"NP",Odsustva!$G$2:$G$500,$B$3,Odsustva!$J$2:$J$500,"<>Otkazano") -> 2 | F13: =SUMIFS(Odsustva!$F$2:$F$500,Odsustva!$B$2:$B$500,$A13,Odsustva!$C$2:$C$500,"OS",Odsustva!$G$2:$G$500,$B$3,Odsustva!$J$2:$J$500,"<>Otkazano") -> 0 | G13: =SUMIFS(Odsustva!$F$2:$F$500,Odsustva!$B$2:$B$500,$A13,Odsustva!$C$2:$C$500,"SV",Odsustva!$G$2:$G$500,$B$3,Odsustva!$J$2:$J$500,"<>Otkazano") -> 0 | H13: =SUM(B13:G13) -> 6
A14: Ivana Rosić | B14: =SUMIFS(Odsustva!$F$2:$F$500,Odsustva!$B$2:$B$500,$A14,Odsustva!$C$2:$C$500,"BO",Odsustva!$G$2:$G$500,$B$3,Odsustva!$J$2:$J$500,"<>Otkazano") -> 0 | C14: =SUMIFS(Odsustva!$F$2:$F$500,Odsustva!$B$2:$B$500,$A14,Odsustva!$C$2:$C$500,"GO",Odsustva!$G$2:$G$500,$B$3,Odsustva!$J$2:$J$500,"<>Otkazano") -> 0 | D14: =SUMIFS(Odsustva!$F$2:$F$500,Odsustva!$B$2:$B$500,$A14,Odsustva!$C$2:$C$500,"FA",Odsustva!$G$2:$G$500,$B$3,Odsustva!$J$2:$J$500,"<>Otkazano") -> 0 | E14: =SUMIFS(Odsustva!$F$2:$F$500,Odsustva!$B$2:$B$500,$A14,Odsustva!$C$2:$C$500,"NP",Odsustva!$G$2:$G$500,$B$3,Odsustva!$J$2:$J$500,"<>Otkazano") -> 0 | F14: =SUMIFS(Odsustva!$F$2:$F$500,Odsustva!$B$2:$B$500,$A14,Odsustva!$C$2:$C$500,"OS",Odsustva!$G$2:$G$500,$B$3,Odsustva!$J$2:$J$500,"<>Otkazano") -> 0 | G14: =SUMIFS(Odsustva!$F$2:$F$500,Odsustva!$B$2:$B$500,$A14,Odsustva!$C$2:$C$500,"SV",Odsustva!$G$2:$G$500,$B$3,Odsustva!$J$2:$J$500,"<>Otkazano") -> 0 | H14: =SUM(B14:G14) -> 0
A15: Maja Petrović | B15: =SUMIFS(Odsustva!$F$2:$F$500,Odsustva!$B$2:$B$500,$A15,Odsustva!$C$2:$C$500,"BO",Odsustva!$G$2:$G$500,$B$3,Odsustva!$J$2:$J$500,"<>Otkazano") -> 0 | C15: =SUMIFS(Odsustva!$F$2:$F$500,Odsustva!$B$2:$B$500,$A15,Odsustva!$C$2:$C$500,"GO",Odsustva!$G$2:$G$500,$B$3,Odsustva!$J$2:$J$500,"<>Otkazano") -> 0 | D15: =SUMIFS(Odsustva!$F$2:$F$500,Odsustva!$B$2:$B$500,$A15,Odsustva!$C$2:$C$500,"FA",Odsustva!$G$2:$G$500,$B$3,Odsustva!$J$2:$J$500,"<>Otkazano") -> 0 | E15: =SUMIFS(Odsustva!$F$2:$F$500,Odsustva!$B$2:$B$500,$A15,Odsustva!$C$2:$C$500,"NP",Odsustva!$G$2:$G$500,$B$3,Odsustva!$J$2:$J$500,"<>Otkazano") -> 0 | F15: =SUMIFS(Odsustva!$F$2:$F$500,Odsustva!$B$2:$B$500,$A15,Odsustva!$C$2:$C$500,"OS",Odsustva!$G$2:$G$500,$B$3,Odsustva!$J$2:$J$500,"<>Otkazano") -> 0 | G15: =SUMIFS(Odsustva!$F$2:$F$500,Odsustva!$B$2:$B$500,$A15,Odsustva!$C$2:$C$500,"SV",Odsustva!$G$2:$G$500,$B$3,Odsustva!$J$2:$J$500,"<>Otkazano") -> 0 | H15: =SUM(B15:G15) -> 0
A16: Ružica Pantović | B16: =SUMIFS(Odsustva!$F$2:$F$500,Odsustva!$B$2:$B$500,$A16,Odsustva!$C$2:$C$500,"BO",Odsustva!$G$2:$G$500,$B$3,Odsustva!$J$2:$J$500,"<>Otkazano") -> 0 | C16: =SUMIFS(Odsustva!$F$2:$F$500,Odsustva!$B$2:$B$500,$A16,Odsustva!$C$2:$C$500,"GO",Odsustva!$G$2:$G$500,$B$3,Odsustva!$J$2:$J$500,"<>Otkazano") -> 0 | D16: =SUMIFS(Odsustva!$F$2:$F$500,Odsustva!$B$2:$B$500,$A16,Odsustva!$C$2:$C$500,"FA",Odsustva!$G$2:$G$500,$B$3,Odsustva!$J$2:$J$500,"<>Otkazano") -> 0 | E16: =SUMIFS(Odsustva!$F$2:$F$500,Odsustva!$B$2:$B$500,$A16,Odsustva!$C$2:$C$500,"NP",Odsustva!$G$2:$G$500,$B$3,Odsustva!$J$2:$J$500,"<>Otkazano") -> 0 | F16: =SUMIFS(Odsustva!$F$2:$F$500,Odsustva!$B$2:$B$500,$A16,Odsustva!$C$2:$C$500,"OS",Odsustva!$G$2:$G$500,$B$3,Odsustva!$J$2:$J$500,"<>Otkazano") -> 0 | G16: =SUMIFS(Odsustva!$F$2:$F$500,Odsustva!$B$2:$B$500,$A16,Odsustva!$C$2:$C$500,"SV",Odsustva!$G$2:$G$500,$B$3,Odsustva!$J$2:$J$500,"<>Otkazano") -> 0 | H16: =SUM(B16:G16) -> 0
A17: Mihailo Savić | B17: =SUMIFS(Odsustva!$F$2:$F$500,Odsustva!$B$2:$B$500,$A17,Odsustva!$C$2:$C$500,"BO",Odsustva!$G$2:$G$500,$B$3,Odsustva!$J$2:$J$500,"<>Otkazano") -> 0 | C17: =SUMIFS(Odsustva!$F$2:$F$500,Odsustva!$B$2:$B$500,$A17,Odsustva!$C$2:$C$500,"GO",Odsustva!$G$2:$G$500,$B$3,Odsustva!$J$2:$J$500,"<>Otkazano") -> 0 | D17: =SUMIFS(Odsustva!$F$2:$F$500,Odsustva!$B$2:$B$500,$A17,Odsustva!$C$2:$C$500,"FA",Odsustva!$G$2:$G$500,$B$3,Odsustva!$J$2:$J$500,"<>Otkazano") -> 0 | E17: =SUMIFS(Odsustva!$F$2:$F$500,Odsustva!$B$2:$B$500,$A17,Odsustva!$C$2:$C$500,"NP",Odsustva!$G$2:$G$500,$B$3,Odsustva!$J$2:$J$500,"<>Otkazano") -> 0 | F17: =SUMIFS(Odsustva!$F$2:$F$500,Odsustva!$B$2:$B$500,$A17,Odsustva!$C$2:$C$500,"OS",Odsustva!$G$2:$G$500,$B$3,Odsustva!$J$2:$J$500,"<>Otkazano") -> 0 | G17: =SUMIFS(Odsustva!$F$2:$F$500,Odsustva!$B$2:$B$500,$A17,Odsustva!$C$2:$C$500,"SV",Odsustva!$G$2:$G$500,$B$3,Odsustva!$J$2:$J$500,"<>Otkazano") -> 0 | H17: =SUM(B17:G17) -> 0
A18: Uroš Velinovski | B18: =SUMIFS(Odsustva!$F$2:$F$500,Odsustva!$B$2:$B$500,$A18,Odsustva!$C$2:$C$500,"BO",Odsustva!$G$2:$G$500,$B$3,Odsustva!$J$2:$J$500,"<>Otkazano") -> 0 | C18: =SUMIFS(Odsustva!$F$2:$F$500,Odsustva!$B$2:$B$500,$A18,Odsustva!$C$2:$C$500,"GO",Odsustva!$G$2:$G$500,$B$3,Odsustva!$J$2:$J$500,"<>Otkazano") -> 0 | D18: =SUMIFS(Odsustva!$F$2:$F$500,Odsustva!$B$2:$B$500,$A18,Odsustva!$C$2:$C$500,"FA",Odsustva!$G$2:$G$500,$B$3,Odsustva!$J$2:$J$500,"<>Otkazano") -> 0 | E18: =SUMIFS(Odsustva!$F$2:$F$500,Odsustva!$B$2:$B$500,$A18,Odsustva!$C$2:$C$500,"NP",Odsustva!$G$2:$G$500,$B$3,Odsustva!$J$2:$J$500,"<>Otkazano") -> 2 | F18: =SUMIFS(Odsustva!$F$2:$F$500,Odsustva!$B$2:$B$500,$A18,Odsustva!$C$2:$C$500,"OS",Odsustva!$G$2:$G$500,$B$3,Odsustva!$J$2:$J$500,"<>Otkazano") -> 0 | G18: =SUMIFS(Odsustva!$F$2:$F$500,Odsustva!$B$2:$B$500,$A18,Odsustva!$C$2:$C$500,"SV",Odsustva!$G$2:$G$500,$B$3,Odsustva!$J$2:$J$500,"<>Otkazano") -> 0 | H18: =SUM(B18:G18) -> 2
... A22: Aleksandar Janković | B22: =SUMIFS(Odsustva!$F$2:$F$500,Odsustva!$B$2:$B$500,$A22,Odsustva!$C$2:$C$500,"BO",Odsustva!$G$2:$G$500,$B$3,Odsustva!$J$2:$J$500,"<>Otkazano") -> 0 | C22: =SUMIFS(Odsustva!$F$2:$F$500,Odsustva!$B$2:$B$500,$A22,Odsustva!$C$2:$C$500,"GO",Odsustva!$G$2:$G$500,$B$3,Odsustva!$J$2:$J$500,"<>Otkazano") -> 0 | D22: =SUMIFS(Odsustva!$F$2:$F$500,Odsustva!$B$2:$B$500,$A22,Odsustva!$C$2:$C$500,"FA",Odsustva!$G$2:$G$500,$B$3,Odsustva!$J$2:$J$500,"<>Otkazano") -> 0 | E22: =SUMIFS(Odsustva!$F$2:$F$500,Odsustva!$B$2:$B$500,$A22,Odsustva!$C$2:$C$500,"NP",Odsustva!$G$2:$G$500,$B$3,Odsustva!$J$2:$J$500,"<>Otkazano") -> 0 | F22: =SUMIFS(Odsustva!$F$2:$F$500,Odsustva!$B$2:$B$500,$A22,Odsustva!$C$2:$C$500,"OS",Odsustva!$G$2:$G$500,$B$3,Odsustva!$J$2:$J$500,"<>Otkazano") -> 0 | G22: =SUMIFS(Odsustva!$F$2:$F$500,Odsustva!$B$2:$B$500,$A22,Odsustva!$C$2:$C$500,"SV",Odsustva!$G$2:$G$500,$B$3,Odsustva!$J$2:$J$500,"<>Otkazano") -> 0 | H22: =SUM(B22:G22) -> 0
A23: UKUPNO | B23: =SUM(B7:B22) -> 0 | C23: =SUM(C7:C22) -> 13 | D23: =SUM(D7:D22) -> 1 | E23: =SUM(E7:E22) -> 10 | F23: =SUM(F7:F22) -> 0 | G23: =SUM(G7:G22) -> 0 | H23: =SUM(H7:H22) -> 24

Sheet GO_Saldo
A1: GO saldo (pregled)
A2: Detaljniji obračun i kontrola: tab 'GO_Saldo_Detaljno'.
A4: Zaposleni | B4: Preneto priznato (dana) | C4: Iskorišćeno + planirano (dana) | D4: Preostalo do kraja (dana) | E4: Napomena
A5: =GO_Saldo_Detaljno!A5 -> Aleksandar Janković | B5: =GO_Saldo_Detaljno!D5 -> 2 | C5: =IFERROR(GO_Saldo_Detaljno!I5+ GO_Saldo_Detaljno!J5,"") -> 0 | D5: =GO_Saldo_Detaljno!L5 -> 22 | E5: =IFERROR("Isk:"&TEXT(GO_Saldo_Detaljno!I5,"0.##")&" | Plan:"&TEXT(GO_Saldo_Detaljno!J5,"0.##"),"") -> Isk:0 | Plan:0
A6: =GO_Saldo_Detaljno!A6 -> Dejan Đorić | B6: =GO_Saldo_Detaljno!D6 -> 14 | C6: =IFERROR(GO_Saldo_Detaljno!I6+ GO_Saldo_Detaljno!J6,"") -> 0 | D6: =GO_Saldo_Detaljno!L6 -> 34 | E6: =IFERROR("Isk:"&TEXT(GO_Saldo_Detaljno!I6,"0.##")&" | Plan:"&TEXT(GO_Saldo_Detaljno!J6,"0.##"),"") -> Isk:0 | Plan:0
A7: =GO_Saldo_Detaljno!A7 -> Dragan Babić | B7: =GO_Saldo_Detaljno!D7 -> 10 | C7: =IFERROR(GO_Saldo_Detaljno!I7+ GO_Saldo_Detaljno!J7,"") -> 0 | D7: =GO_Saldo_Detaljno!L7 -> 30 | E7: =IFERROR("Isk:"&TEXT(GO_Saldo_Detaljno!I7,"0.##")&" | Plan:"&TEXT(GO_Saldo_Detaljno!J7,"0.##"),"") -> Isk:0 | Plan:0
A8: =GO_Saldo_Detaljno!A8 -> Ivana Rosić | B8: =GO_Saldo_Detaljno!D8 -> 7 | C8: =IFERROR(GO_Saldo_Detaljno!I8+ GO_Saldo_Detaljno!J8,"") -> 0 | D8: =GO_Saldo_Detaljno!L8 -> 27 | E8: =IFERROR("Isk:"&TEXT(GO_Saldo_Detaljno!I8,"0.##")&" | Plan:"&TEXT(GO_Saldo_Detaljno!J8,"0.##"),"") -> Isk:0 | Plan:0
A9: =GO_Saldo_Detaljno!A9 -> Luka Kostov Drndarski | B9: =GO_Saldo_Detaljno!D9 -> 10 | C9: =IFERROR(GO_Saldo_Detaljno!I9+ GO_Saldo_Detaljno!J9,"") -> 0 | D9: =GO_Saldo_Detaljno!L9 -> 30 | E9: =IFERROR("Isk:"&TEXT(GO_Saldo_Detaljno!I9,"0.##")&" | Plan:"&TEXT(GO_Saldo_Detaljno!J9,"0.##"),"") -> Isk:0 | Plan:0
A10: =GO_Saldo_Detaljno!A10 -> Luka Pandurov | B10: =GO_Saldo_Detaljno!D10 -> 15 | C10: =IFERROR(GO_Saldo_Detaljno!I10+ GO_Saldo_Detaljno!J10,"") -> 5 | D10: =GO_Saldo_Detaljno!L10 -> 25 | E10: =IFERROR("Isk:"&TEXT(GO_Saldo_Detaljno!I10,"0.##")&" | Plan:"&TEXT(GO_Saldo_Detaljno!J10,"0.##"),"") -> Isk:05 | Plan:0
A11: =GO_Saldo_Detaljno!A11 -> Maja Petrović | B11: =GO_Saldo_Detaljno!D11 -> 16 | C11: =IFERROR(GO_Saldo_Detaljno!I11+ GO_Saldo_Detaljno!J11,"") -> 0 | D11: =GO_Saldo_Detaljno!L11 -> 36 | E11: =IFERROR("Isk:"&TEXT(GO_Saldo_Detaljno!I11,"0.##")&" | Plan:"&TEXT(GO_Saldo_Detaljno!J11,"0.##"),"") -> Isk:0 | Plan:0
A12: =GO_Saldo_Detaljno!A12 -> Mihailo Savić | B12: =GO_Saldo_Detaljno!D12 -> 10 | C12: =IFERROR(GO_Saldo_Detaljno!I12+ GO_Saldo_Detaljno!J12,"") -> 0 | D12: =GO_Saldo_Detaljno!L12 -> 30 | E12: =IFERROR("Isk:"&TEXT(GO_Saldo_Detaljno!I12,"0.##")&" | Plan:"&TEXT(GO_Saldo_Detaljno!J12,"0.##"),"") -> Isk:0 | Plan:0
A13: =GO_Saldo_Detaljno!A13 -> Milica Milisavljević | B13: =GO_Saldo_Detaljno!D13 -> 18 | C13: =IFERROR(GO_Saldo_Detaljno!I13+ GO_Saldo_Detaljno!J13,"") -> 0 | D13: =GO_Saldo_Detaljno!L13 -> 38 | E13: =IFERROR("Isk:"&TEXT(GO_Saldo_Detaljno!I13,"0.##")&" | Plan:"&TEXT(GO_Saldo_Detaljno!J13,"0.##"),"") -> Isk:0 | Plan:0
A14: =GO_Saldo_Detaljno!A14 -> Mina Simonović | B14: =GO_Saldo_Detaljno!D14 -> 5 | C14: =IFERROR(GO_Saldo_Detaljno!I14+ GO_Saldo_Detaljno!J14,"") -> 0 | D14: =GO_Saldo_Detaljno!L14 -> 25 | E14: =IFERROR("Isk:"&TEXT(GO_Saldo_Detaljno!I14,"0.##")&" | Plan:"&TEXT(GO_Saldo_Detaljno!J14,"0.##"),"") -> Isk:0 | Plan:0
A15: =GO_Saldo_Detaljno!A15 -> Nikola Lazarević | B15: =GO_Saldo_Detaljno!D15 -> 13 | C15: =IFERROR(GO_Saldo_Detaljno!I15+ GO_Saldo_Detaljno!J15,"") -> 0 | D15: =GO_Saldo_Detaljno!L15 -> 33 | E15: =IFERROR("Isk:"&TEXT(GO_Saldo_Detaljno!I15,"0.##")&" | Plan:"&TEXT(GO_Saldo_Detaljno!J15,"0.##"),"") -> Isk:0 | Plan:0
A16: =GO_Saldo_Detaljno!A16 -> Olga Jovanović | B16: =GO_Saldo_Detaljno!D16 -> 4 | C16: =IFERROR(GO_Saldo_Detaljno!I16+ GO_Saldo_Detaljno!J16,"") -> 0 | D16: =GO_Saldo_Detaljno!L16 -> 24 | E16: =IFERROR("Isk:"&TEXT(GO_Saldo_Detaljno!I16,"0.##")&" | Plan:"&TEXT(GO_Saldo_Detaljno!J16,"0.##"),"") -> Isk:0 | Plan:0
... A20: =GO_Saldo_Detaljno!A20 -> Stevo Ljubičić | B20: =GO_Saldo_Detaljno!D20 -> 6 | C20: =IFERROR(GO_Saldo_Detaljno!I20+ GO_Saldo_Detaljno!J20,"") -> 6 | D20: =GO_Saldo_Detaljno!L20 -> 14 | E20: =IFERROR("Isk:"&TEXT(GO_Saldo_Detaljno!I20,"0.##")&" | Plan:"&TEXT(GO_Saldo_Detaljno!J20,"0.##"),"") -> Isk:02 | Plan:04
A21: =GO_Saldo_Detaljno!B21 -> 14 | B21: =GO_Saldo_Detaljno!D21 -> 14 | C21: =IFERROR(GO_Saldo_Detaljno!I21+ GO_Saldo_Detaljno!J21,"") -> 2 | D21: =GO_Saldo_Detaljno!L21 -> 30 | E21: =IFERROR("Isk:"&TEXT(GO_Saldo_Detaljno!I21,"0.##")&" | Plan:"&TEXT(GO_Saldo_Detaljno!J21,"0.##"),"") -> Isk:02 | Plan:0

Sheet GO_Saldo_Detaljno
A1: Izabrana godina | B1: 2026 | D1: Rok prenetog GO | E1: =DATE($B$1,MONTH(Pravila!$B$3),DAY(Pravila!$B$3)) -> 46203
A2: Današnji datum | B2: =TODAY() -> 46140 | D2: Max prenos (dana) | E2: =Pravila!$B$2 -> 20
A4: Zaposleni | B4: GO preneto (unos) | C4: GO kvota (unos) | D4: GO preneto priznato | E4: Odsustva (umanjuje GO) iskorišćeno do 30.06 | F4: GO preneto preostalo (validno do 30.06) | G4: GO preneto izgubljeno (posle 30.06) | H4: GO raspoloživo danas | I4: Odsustva (umanjuje GO) iskorišćeno do danas | J4: Odsustva (umanjuje GO) planirano do kraja godine | K4: GO preostalo danas | L4: GO preostalo posle planiranog
A5: {=_xlfn.ANCHORARRAY(Zaposleni!I2)} -> Aleksandar Janković | B5: =IF($A5="","", _xlfn.XLOOKUP($A5, Zaposleni!$B$2:$B$200, Zaposleni!$G$2:$G$200, "")) -> 2 | C5: =IF($A5="","", _xlfn.XLOOKUP($A5, Zaposleni!$B$2:$B$200, Zaposleni!$H$2:$H$200, "")) -> 20 | D5: =MIN(B5,$E$2) -> 2 | E5: =SUMIFS(Odsustva!$F$2:$F$500,Odsustva!$B$2:$B$500,$A5,Odsustva!$G$2:$G$500,$B$1,Odsustva!$E$2:$E$500,"<="&$E$1,Odsustva!$K$2:$K$500,"DA",Odsustva!$J$2:$J$500,"Odobreno")+SUMIFS(Odsustva!$F$2:$F$500,Odsustva!$B$2:$B$500,$A5,Odsustva!$G$2:$G$500,$B$1,Odsustva!$E$2:$E$500,"<="&$E$1,Odsustva!$K$2:$K$500,"DA",Odsustva!$J$2:$J$500,"Evidentirano") -> 0 | F5: =MAX(0,D5-E5) -> 2 | G5: =IF($B$2>$E$1,F5,0) -> 0 | H5: =C5+IF($B$2<=$E$1,F5,0) -> 22 | I5: =SUMIFS(Odsustva!$F$2:$F$500,Odsustva!$B$2:$B$500,$A5,Odsustva!$G$2:$G$500,$B$1,Odsustva!$E$2:$E$500,"<="&$B$2,Odsustva!$K$2:$K$500,"DA",Odsustva!$J$2:$J$500,"Odobreno")+SUMIFS(Odsustva!$F$2:$F$500,Odsustva!$B$2:$B$500,$A5,Odsustva!$G$2:$G$500,$B$1,Odsustva!$E$2:$E$500,"<="&$B$2,Odsustva!$K$2:$K$500,"DA",Odsustva!$J$2:$J$500,"Evidentirano") -> 0 | J5: =SUMIFS(Odsustva!$F$2:$F$500,Odsustva!$B$2:$B$500,$A5,Odsustva!$G$2:$G$500,$B$1,Odsustva!$D$2:$D$500,">"&$B$2,Odsustva!$K$2:$K$500,"DA",Odsustva!$J$2:$J$500,"Planirano")+SUMIFS(Odsustva!$F$2:$F$500,Odsustva!$B$2:$B$500,$A5,Odsustva!$G$2:$G$500,$B$1,Odsustva!$D$2:$D$500,">"&$B$2,Odsustva!$K$2:$K$500,"DA",Odsustva!$J$2:$J$500,"Odobreno") -> 0 | K5: =H5-I5 -> 22 | L5: =K5-J5 -> 22
A6: Dejan Đorić | B6: =IF($A6="","", _xlfn.XLOOKUP($A6, Zaposleni!$B$2:$B$200, Zaposleni!$G$2:$G$200, "")) -> 14 | C6: =IF($A6="","", _xlfn.XLOOKUP($A6, Zaposleni!$B$2:$B$200, Zaposleni!$H$2:$H$200, "")) -> 20 | D6: =MIN(B6,$E$2) -> 14 | E6: =SUMIFS(Odsustva!$F$2:$F$500,Odsustva!$B$2:$B$500,$A6,Odsustva!$G$2:$G$500,$B$1,Odsustva!$E$2:$E$500,"<="&$E$1,Odsustva!$K$2:$K$500,"DA",Odsustva!$J$2:$J$500,"Odobreno")+SUMIFS(Odsustva!$F$2:$F$500,Odsustva!$B$2:$B$500,$A6,Odsustva!$G$2:$G$500,$B$1,Odsustva!$E$2:$E$500,"<="&$E$1,Odsustva!$K$2:$K$500,"DA",Odsustva!$J$2:$J$500,"Evidentirano") -> 0 | F6: =MAX(0,D6-E6) -> 14 | G6: =IF($B$2>$E$1,F6,0) -> 0 | H6: =C6+IF($B$2<=$E$1,F6,0) -> 34 | I6: =SUMIFS(Odsustva!$F$2:$F$500,Odsustva!$B$2:$B$500,$A6,Odsustva!$G$2:$G$500,$B$1,Odsustva!$E$2:$E$500,"<="&$B$2,Odsustva!$K$2:$K$500,"DA",Odsustva!$J$2:$J$500,"Odobreno")+SUMIFS(Odsustva!$F$2:$F$500,Odsustva!$B$2:$B$500,$A6,Odsustva!$G$2:$G$500,$B$1,Odsustva!$E$2:$E$500,"<="&$B$2,Odsustva!$K$2:$K$500,"DA",Odsustva!$J$2:$J$500,"Evidentirano") -> 0 | J6: =SUMIFS(Odsustva!$F$2:$F$500,Odsustva!$B$2:$B$500,$A6,Odsustva!$G$2:$G$500,$B$1,Odsustva!$D$2:$D$500,">"&$B$2,Odsustva!$K$2:$K$500,"DA",Odsustva!$J$2:$J$500,"Planirano")+SUMIFS(Odsustva!$F$2:$F$500,Odsustva!$B$2:$B$500,$A6,Odsustva!$G$2:$G$500,$B$1,Odsustva!$D$2:$D$500,">"&$B$2,Odsustva!$K$2:$K$500,"DA",Odsustva!$J$2:$J$500,"Odobreno") -> 0 | K6: =H6-I6 -> 34 | L6: =K6-J6 -> 34
A7: Dragan Babić | B7: =IF($A7="","", _xlfn.XLOOKUP($A7, Zaposleni!$B$2:$B$200, Zaposleni!$G$2:$G$200, "")) -> 10 | C7: =IF($A7="","", _xlfn.XLOOKUP($A7, Zaposleni!$B$2:$B$200, Zaposleni!$H$2:$H$200, "")) -> 20 | D7: =MIN(B7,$E$2) -> 10 | E7: =SUMIFS(Odsustva!$F$2:$F$500,Odsustva!$B$2:$B$500,$A7,Odsustva!$G$2:$G$500,$B$1,Odsustva!$E$2:$E$500,"<="&$E$1,Odsustva!$K$2:$K$500,"DA",Odsustva!$J$2:$J$500,"Odobreno")+SUMIFS(Odsustva!$F$2:$F$500,Odsustva!$B$2:$B$500,$A7,Odsustva!$G$2:$G$500,$B$1,Odsustva!$E$2:$E$500,"<="&$E$1,Odsustva!$K$2:$K$500,"DA",Odsustva!$J$2:$J$500,"Evidentirano") -> 0 | F7: =MAX(0,D7-E7) -> 10 | G7: =IF($B$2>$E$1,F7,0) -> 0 | H7: =C7+IF($B$2<=$E$1,F7,0) -> 30 | I7: =SUMIFS(Odsustva!$F$2:$F$500,Odsustva!$B$2:$B$500,$A7,Odsustva!$G$2:$G$500,$B$1,Odsustva!$E$2:$E$500,"<="&$B$2,Odsustva!$K$2:$K$500,"DA",Odsustva!$J$2:$J$500,"Odobreno")+SUMIFS(Odsustva!$F$2:$F$500,Odsustva!$B$2:$B$500,$A7,Odsustva!$G$2:$G$500,$B$1,Odsustva!$E$2:$E$500,"<="&$B$2,Odsustva!$K$2:$K$500,"DA",Odsustva!$J$2:$J$500,"Evidentirano") -> 0 | J7: =SUMIFS(Odsustva!$F$2:$F$500,Odsustva!$B$2:$B$500,$A7,Odsustva!$G$2:$G$500,$B$1,Odsustva!$D$2:$D$500,">"&$B$2,Odsustva!$K$2:$K$500,"DA",Odsustva!$J$2:$J$500,"Planirano")+SUMIFS(Odsustva!$F$2:$F$500,Odsustva!$B$2:$B$500,$A7,Odsustva!$G$2:$G$500,$B$1,Odsustva!$D$2:$D$500,">"&$B$2,Odsustva!$K$2:$K$500,"DA",Odsustva!$J$2:$J$500,"Odobreno") -> 0 | K7: =H7-I7 -> 30 | L7: =K7-J7 -> 30
A8: Ivana Rosić | B8: =IF($A8="","", _xlfn.XLOOKUP($A8, Zaposleni!$B$2:$B$200, Zaposleni!$G$2:$G$200, "")) -> 7 | C8: =IF($A8="","", _xlfn.XLOOKUP($A8, Zaposleni!$B$2:$B$200, Zaposleni!$H$2:$H$200, "")) -> 20 | D8: =MIN(B8,$E$2) -> 7 | E8: =SUMIFS(Odsustva!$F$2:$F$500,Odsustva!$B$2:$B$500,$A8,Odsustva!$G$2:$G$500,$B$1,Odsustva!$E$2:$E$500,"<="&$E$1,Odsustva!$K$2:$K$500,"DA",Odsustva!$J$2:$J$500,"Odobreno")+SUMIFS(Odsustva!$F$2:$F$500,Odsustva!$B$2:$B$500,$A8,Odsustva!$G$2:$G$500,$B$1,Odsustva!$E$2:$E$500,"<="&$E$1,Odsustva!$K$2:$K$500,"DA",Odsustva!$J$2:$J$500,"Evidentirano") -> 0 | F8: =MAX(0,D8-E8) -> 7 | G8: =IF($B$2>$E$1,F8,0) -> 0 | H8: =C8+IF($B$2<=$E$1,F8,0) -> 27 | I8: =SUMIFS(Odsustva!$F$2:$F$500,Odsustva!$B$2:$B$500,$A8,Odsustva!$G$2:$G$500,$B$1,Odsustva!$E$2:$E$500,"<="&$B$2,Odsustva!$K$2:$K$500,"DA",Odsustva!$J$2:$J$500,"Odobreno")+SUMIFS(Odsustva!$F$2:$F$500,Odsustva!$B$2:$B$500,$A8,Odsustva!$G$2:$G$500,$B$1,Odsustva!$E$2:$E$500,"<="&$B$2,Odsustva!$K$2:$K$500,"DA",Odsustva!$J$2:$J$500,"Evidentirano") -> 0 | J8: =SUMIFS(Odsustva!$F$2:$F$500,Odsustva!$B$2:$B$500,$A8,Odsustva!$G$2:$G$500,$B$1,Odsustva!$D$2:$D$500,">"&$B$2,Odsustva!$K$2:$K$500,"DA",Odsustva!$J$2:$J$500,"Planirano")+SUMIFS(Odsustva!$F$2:$F$500,Odsustva!$B$2:$B$500,$A8,Odsustva!$G$2:$G$500,$B$1,Odsustva!$D$2:$D$500,">"&$B$2,Odsustva!$K$2:$K$500,"DA",Odsustva!$J$2:$J$500,"Odobreno") -> 0 | K8: =H8-I8 -> 27 | L8: =K8-J8 -> 27
A9: Luka Kostov Drndarski | B9: =IF($A9="","", _xlfn.XLOOKUP($A9, Zaposleni!$B$2:$B$200, Zaposleni!$G$2:$G$200, "")) -> 10 | C9: =IF($A9="","", _xlfn.XLOOKUP($A9, Zaposleni!$B$2:$B$200, Zaposleni!$H$2:$H$200, "")) -> 20 | D9: =MIN(B9,$E$2) -> 10 | E9: =SUMIFS(Odsustva!$F$2:$F$500,Odsustva!$B$2:$B$500,$A9,Odsustva!$G$2:$G$500,$B$1,Odsustva!$E$2:$E$500,"<="&$E$1,Odsustva!$K$2:$K$500,"DA",Odsustva!$J$2:$J$500,"Odobreno")+SUMIFS(Odsustva!$F$2:$F$500,Odsustva!$B$2:$B$500,$A9,Odsustva!$G$2:$G$500,$B$1,Odsustva!$E$2:$E$500,"<="&$E$1,Odsustva!$K$2:$K$500,"DA",Odsustva!$J$2:$J$500,"Evidentirano") -> 0 | F9: =MAX(0,D9-E9) -> 10 | G9: =IF($B$2>$E$1,F9,0) -> 0 | H9: =C9+IF($B$2<=$E$1,F9,0) -> 30 | I9: =SUMIFS(Odsustva!$F$2:$F$500,Odsustva!$B$2:$B$500,$A9,Odsustva!$G$2:$G$500,$B$1,Odsustva!$E$2:$E$500,"<="&$B$2,Odsustva!$K$2:$K$500,"DA",Odsustva!$J$2:$J$500,"Odobreno")+SUMIFS(Odsustva!$F$2:$F$500,Odsustva!$B$2:$B$500,$A9,Odsustva!$G$2:$G$500,$B$1,Odsustva!$E$2:$E$500,"<="&$B$2,Odsustva!$K$2:$K$500,"DA",Odsustva!$J$2:$J$500,"Evidentirano") -> 0 | J9: =SUMIFS(Odsustva!$F$2:$F$500,Odsustva!$B$2:$B$500,$A9,Odsustva!$G$2:$G$500,$B$1,Odsustva!$D$2:$D$500,">"&$B$2,Odsustva!$K$2:$K$500,"DA",Odsustva!$J$2:$J$500,"Planirano")+SUMIFS(Odsustva!$F$2:$F$500,Odsustva!$B$2:$B$500,$A9,Odsustva!$G$2:$G$500,$B$1,Odsustva!$D$2:$D$500,">"&$B$2,Odsustva!$K$2:$K$500,"DA",Odsustva!$J$2:$J$500,"Odobreno") -> 0 | K9: =H9-I9 -> 30 | L9: =K9-J9 -> 30
A10: Luka Pandurov | B10: =IF($A10="","", _xlfn.XLOOKUP($A10, Zaposleni!$B$2:$B$200, Zaposleni!$G$2:$G$200, "")) -> 15 | C10: =IF($A10="","", _xlfn.XLOOKUP($A10, Zaposleni!$B$2:$B$200, Zaposleni!$H$2:$H$200, "")) -> 20 | D10: =MIN(B10,$E$2) -> 15 | E10: =SUMIFS(Odsustva!$F$2:$F$500,Odsustva!$B$2:$B$500,$A10,Odsustva!$G$2:$G$500,$B$1,Odsustva!$E$2:$E$500,"<="&$E$1,Odsustva!$K$2:$K$500,"DA",Odsustva!$J$2:$J$500,"Odobreno")+SUMIFS(Odsustva!$F$2:$F$500,Odsustva!$B$2:$B$500,$A10,Odsustva!$G$2:$G$500,$B$1,Odsustva!$E$2:$E$500,"<="&$E$1,Odsustva!$K$2:$K$500,"DA",Odsustva!$J$2:$J$500,"Evidentirano") -> 5 | F10: =MAX(0,D10-E10) -> 10 | G10: =IF($B$2>$E$1,F10,0) -> 0 | H10: =C10+IF($B$2<=$E$1,F10,0) -> 30 | I10: =SUMIFS(Odsustva!$F$2:$F$500,Odsustva!$B$2:$B$500,$A10,Odsustva!$G$2:$G$500,$B$1,Odsustva!$E$2:$E$500,"<="&$B$2,Odsustva!$K$2:$K$500,"DA",Odsustva!$J$2:$J$500,"Odobreno")+SUMIFS(Odsustva!$F$2:$F$500,Odsustva!$B$2:$B$500,$A10,Odsustva!$G$2:$G$500,$B$1,Odsustva!$E$2:$E$500,"<="&$B$2,Odsustva!$K$2:$K$500,"DA",Odsustva!$J$2:$J$500,"Evidentirano") -> 5 | J10: =SUMIFS(Odsustva!$F$2:$F$500,Odsustva!$B$2:$B$500,$A10,Odsustva!$G$2:$G$500,$B$1,Odsustva!$D$2:$D$500,">"&$B$2,Odsustva!$K$2:$K$500,"DA",Odsustva!$J$2:$J$500,"Planirano")+SUMIFS(Odsustva!$F$2:$F$500,Odsustva!$B$2:$B$500,$A10,Odsustva!$G$2:$G$500,$B$1,Odsustva!$D$2:$D$500,">"&$B$2,Odsustva!$K$2:$K$500,"DA",Odsustva!$J$2:$J$500,"Odobreno") -> 0 | K10: =H10-I10 -> 25 | L10: =K10-J10 -> 25
A11: Maja Petrović | B11: =IF($A11="","", _xlfn.XLOOKUP($A11, Zaposleni!$B$2:$B$200, Zaposleni!$G$2:$G$200, "")) -> 16 | C11: =IF($A11="","", _xlfn.XLOOKUP($A11, Zaposleni!$B$2:$B$200, Zaposleni!$H$2:$H$200, "")) -> 20 | D11: =MIN(B11,$E$2) -> 16 | E11: =SUMIFS(Odsustva!$F$2:$F$500,Odsustva!$B$2:$B$500,$A11,Odsustva!$G$2:$G$500,$B$1,Odsustva!$E$2:$E$500,"<="&$E$1,Odsustva!$K$2:$K$500,"DA",Odsustva!$J$2:$J$500,"Odobreno")+SUMIFS(Odsustva!$F$2:$F$500,Odsustva!$B$2:$B$500,$A11,Odsustva!$G$2:$G$500,$B$1,Odsustva!$E$2:$E$500,"<="&$E$1,Odsustva!$K$2:$K$500,"DA",Odsustva!$J$2:$J$500,"Evidentirano") -> 0 | F11: =MAX(0,D11-E11) -> 16 | G11: =IF($B$2>$E$1,F11,0) -> 0 | H11: =C11+IF($B$2<=$E$1,F11,0) -> 36 | I11: =SUMIFS(Odsustva!$F$2:$F$500,Odsustva!$B$2:$B$500,$A11,Odsustva!$G$2:$G$500,$B$1,Odsustva!$E$2:$E$500,"<="&$B$2,Odsustva!$K$2:$K$500,"DA",Odsustva!$J$2:$J$500,"Odobreno")+SUMIFS(Odsustva!$F$2:$F$500,Odsustva!$B$2:$B$500,$A11,Odsustva!$G$2:$G$500,$B$1,Odsustva!$E$2:$E$500,"<="&$B$2,Odsustva!$K$2:$K$500,"DA",Odsustva!$J$2:$J$500,"Evidentirano") -> 0 | J11: =SUMIFS(Odsustva!$F$2:$F$500,Odsustva!$B$2:$B$500,$A11,Odsustva!$G$2:$G$500,$B$1,Odsustva!$D$2:$D$500,">"&$B$2,Odsustva!$K$2:$K$500,"DA",Odsustva!$J$2:$J$500,"Planirano")+SUMIFS(Odsustva!$F$2:$F$500,Odsustva!$B$2:$B$500,$A11,Odsustva!$G$2:$G$500,$B$1,Odsustva!$D$2:$D$500,">"&$B$2,Odsustva!$K$2:$K$500,"DA",Odsustva!$J$2:$J$500,"Odobreno") -> 0 | K11: =H11-I11 -> 36 | L11: =K11-J11 -> 36
A12: Mihailo Savić | B12: =IF($A12="","", _xlfn.XLOOKUP($A12, Zaposleni!$B$2:$B$200, Zaposleni!$G$2:$G$200, "")) -> 10 | C12: =IF($A12="","", _xlfn.XLOOKUP($A12, Zaposleni!$B$2:$B$200, Zaposleni!$H$2:$H$200, "")) -> 20 | D12: =MIN(B12,$E$2) -> 10 | E12: =SUMIFS(Odsustva!$F$2:$F$500,Odsustva!$B$2:$B$500,$A12,Odsustva!$G$2:$G$500,$B$1,Odsustva!$E$2:$E$500,"<="&$E$1,Odsustva!$K$2:$K$500,"DA",Odsustva!$J$2:$J$500,"Odobreno")+SUMIFS(Odsustva!$F$2:$F$500,Odsustva!$B$2:$B$500,$A12,Odsustva!$G$2:$G$500,$B$1,Odsustva!$E$2:$E$500,"<="&$E$1,Odsustva!$K$2:$K$500,"DA",Odsustva!$J$2:$J$500,"Evidentirano") -> 0 | F12: =MAX(0,D12-E12) -> 10 | G12: =IF($B$2>$E$1,F12,0) -> 0 | H12: =C12+IF($B$2<=$E$1,F12,0) -> 30 | I12: =SUMIFS(Odsustva!$F$2:$F$500,Odsustva!$B$2:$B$500,$A12,Odsustva!$G$2:$G$500,$B$1,Odsustva!$E$2:$E$500,"<="&$B$2,Odsustva!$K$2:$K$500,"DA",Odsustva!$J$2:$J$500,"Odobreno")+SUMIFS(Odsustva!$F$2:$F$500,Odsustva!$B$2:$B$500,$A12,Odsustva!$G$2:$G$500,$B$1,Odsustva!$E$2:$E$500,"<="&$B$2,Odsustva!$K$2:$K$500,"DA",Odsustva!$J$2:$J$500,"Evidentirano") -> 0 | J12: =SUMIFS(Odsustva!$F$2:$F$500,Odsustva!$B$2:$B$500,$A12,Odsustva!$G$2:$G$500,$B$1,Odsustva!$D$2:$D$500,">"&$B$2,Odsustva!$K$2:$K$500,"DA",Odsustva!$J$2:$J$500,"Planirano")+SUMIFS(Odsustva!$F$2:$F$500,Odsustva!$B$2:$B$500,$A12,Odsustva!$G$2:$G$500,$B$1,Odsustva!$D$2:$D$500,">"&$B$2,Odsustva!$K$2:$K$500,"DA",Odsustva!$J$2:$J$500,"Odobreno") -> 0 | K12: =H12-I12 -> 30 | L12: =K12-J12 -> 30
A13: Milica Milisavljević | B13: =IF($A13="","", _xlfn.XLOOKUP($A13, Zaposleni!$B$2:$B$200, Zaposleni!$G$2:$G$200, "")) -> 18 | C13: =IF($A13="","", _xlfn.XLOOKUP($A13, Zaposleni!$B$2:$B$200, Zaposleni!$H$2:$H$200, "")) -> 20 | D13: =MIN(B13,$E$2) -> 18 | E13: =SUMIFS(Odsustva!$F$2:$F$500,Odsustva!$B$2:$B$500,$A13,Odsustva!$G$2:$G$500,$B$1,Odsustva!$E$2:$E$500,"<="&$E$1,Odsustva!$K$2:$K$500,"DA",Odsustva!$J$2:$J$500,"Odobreno")+SUMIFS(Odsustva!$F$2:$F$500,Odsustva!$B$2:$B$500,$A13,Odsustva!$G$2:$G$500,$B$1,Odsustva!$E$2:$E$500,"<="&$E$1,Odsustva!$K$2:$K$500,"DA",Odsustva!$J$2:$J$500,"Evidentirano") -> 0 | F13: =MAX(0,D13-E13) -> 18 | G13: =IF($B$2>$E$1,F13,0) -> 0 | H13: =C13+IF($B$2<=$E$1,F13,0) -> 38 | I13: =SUMIFS(Odsustva!$F$2:$F$500,Odsustva!$B$2:$B$500,$A13,Odsustva!$G$2:$G$500,$B$1,Odsustva!$E$2:$E$500,"<="&$B$2,Odsustva!$K$2:$K$500,"DA",Odsustva!$J$2:$J$500,"Odobreno")+SUMIFS(Odsustva!$F$2:$F$500,Odsustva!$B$2:$B$500,$A13,Odsustva!$G$2:$G$500,$B$1,Odsustva!$E$2:$E$500,"<="&$B$2,Odsustva!$K$2:$K$500,"DA",Odsustva!$J$2:$J$500,"Evidentirano") -> 0 | J13: =SUMIFS(Odsustva!$F$2:$F$500,Odsustva!$B$2:$B$500,$A13,Odsustva!$G$2:$G$500,$B$1,Odsustva!$D$2:$D$500,">"&$B$2,Odsustva!$K$2:$K$500,"DA",Odsustva!$J$2:$J$500,"Planirano")+SUMIFS(Odsustva!$F$2:$F$500,Odsustva!$B$2:$B$500,$A13,Odsustva!$G$2:$G$500,$B$1,Odsustva!$D$2:$D$500,">"&$B$2,Odsustva!$K$2:$K$500,"DA",Odsustva!$J$2:$J$500,"Odobreno") -> 0 | K13: =H13-I13 -> 38 | L13: =K13-J13 -> 38
A14: Mina Simonović | B14: =IF($A14="","", _xlfn.XLOOKUP($A14, Zaposleni!$B$2:$B$200, Zaposleni!$G$2:$G$200, "")) -> 5 | C14: =IF($A14="","", _xlfn.XLOOKUP($A14, Zaposleni!$B$2:$B$200, Zaposleni!$H$2:$H$200, "")) -> 20 | D14: =MIN(B14,$E$2) -> 5 | E14: =SUMIFS(Odsustva!$F$2:$F$500,Odsustva!$B$2:$B$500,$A14,Odsustva!$G$2:$G$500,$B$1,Odsustva!$E$2:$E$500,"<="&$E$1,Odsustva!$K$2:$K$500,"DA",Odsustva!$J$2:$J$500,"Odobreno")+SUMIFS(Odsustva!$F$2:$F$500,Odsustva!$B$2:$B$500,$A14,Odsustva!$G$2:$G$500,$B$1,Odsustva!$E$2:$E$500,"<="&$E$1,Odsustva!$K$2:$K$500,"DA",Odsustva!$J$2:$J$500,"Evidentirano") -> 0 | F14: =MAX(0,D14-E14) -> 5 | G14: =IF($B$2>$E$1,F14,0) -> 0 | H14: =C14+IF($B$2<=$E$1,F14,0) -> 25 | I14: =SUMIFS(Odsustva!$F$2:$F$500,Odsustva!$B$2:$B$500,$A14,Odsustva!$G$2:$G$500,$B$1,Odsustva!$E$2:$E$500,"<="&$B$2,Odsustva!$K$2:$K$500,"DA",Odsustva!$J$2:$J$500,"Odobreno")+SUMIFS(Odsustva!$F$2:$F$500,Odsustva!$B$2:$B$500,$A14,Odsustva!$G$2:$G$500,$B$1,Odsustva!$E$2:$E$500,"<="&$B$2,Odsustva!$K$2:$K$500,"DA",Odsustva!$J$2:$J$500,"Evidentirano") -> 0 | J14: =SUMIFS(Odsustva!$F$2:$F$500,Odsustva!$B$2:$B$500,$A14,Odsustva!$G$2:$G$500,$B$1,Odsustva!$D$2:$D$500,">"&$B$2,Odsustva!$K$2:$K$500,"DA",Odsustva!$J$2:$J$500,"Planirano")+SUMIFS(Odsustva!$F$2:$F$500,Odsustva!$B$2:$B$500,$A14,Odsustva!$G$2:$G$500,$B$1,Odsustva!$D$2:$D$500,">"&$B$2,Odsustva!$K$2:$K$500,"DA",Odsustva!$J$2:$J$500,"Odobreno") -> 0 | K14: =H14-I14 -> 25 | L14: =K14-J14 -> 25
A15: Nikola Lazarević | B15: =IF($A15="","", _xlfn.XLOOKUP($A15, Zaposleni!$B$2:$B$200, Zaposleni!$G$2:$G$200, "")) -> 13 | C15: =IF($A15="","", _xlfn.XLOOKUP($A15, Zaposleni!$B$2:$B$200, Zaposleni!$H$2:$H$200, "")) -> 20 | D15: =MIN(B15,$E$2) -> 13 | E15: =SUMIFS(Odsustva!$F$2:$F$500,Odsustva!$B$2:$B$500,$A15,Odsustva!$G$2:$G$500,$B$1,Odsustva!$E$2:$E$500,"<="&$E$1,Odsustva!$K$2:$K$500,"DA",Odsustva!$J$2:$J$500,"Odobreno")+SUMIFS(Odsustva!$F$2:$F$500,Odsustva!$B$2:$B$500,$A15,Odsustva!$G$2:$G$500,$B$1,Odsustva!$E$2:$E$500,"<="&$E$1,Odsustva!$K$2:$K$500,"DA",Odsustva!$J$2:$J$500,"Evidentirano") -> 0 | F15: =MAX(0,D15-E15) -> 13 | G15: =IF($B$2>$E$1,F15,0) -> 0 | H15: =C15+IF($B$2<=$E$1,F15,0) -> 33 | I15: =SUMIFS(Odsustva!$F$2:$F$500,Odsustva!$B$2:$B$500,$A15,Odsustva!$G$2:$G$500,$B$1,Odsustva!$E$2:$E$500,"<="&$B$2,Odsustva!$K$2:$K$500,"DA",Odsustva!$J$2:$J$500,"Odobreno")+SUMIFS(Odsustva!$F$2:$F$500,Odsustva!$B$2:$B$500,$A15,Odsustva!$G$2:$G$500,$B$1,Odsustva!$E$2:$E$500,"<="&$B$2,Odsustva!$K$2:$K$500,"DA",Odsustva!$J$2:$J$500,"Evidentirano") -> 0 | J15: =SUMIFS(Odsustva!$F$2:$F$500,Odsustva!$B$2:$B$500,$A15,Odsustva!$G$2:$G$500,$B$1,Odsustva!$D$2:$D$500,">"&$B$2,Odsustva!$K$2:$K$500,"DA",Odsustva!$J$2:$J$500,"Planirano")+SUMIFS(Odsustva!$F$2:$F$500,Odsustva!$B$2:$B$500,$A15,Odsustva!$G$2:$G$500,$B$1,Odsustva!$D$2:$D$500,">"&$B$2,Odsustva!$K$2:$K$500,"DA",Odsustva!$J$2:$J$500,"Odobreno") -> 0 | K15: =H15-I15 -> 33 | L15: =K15-J15 -> 33
A16: Olga Jovanović | B16: =IF($A16="","", _xlfn.XLOOKUP($A16, Zaposleni!$B$2:$B$200, Zaposleni!$G$2:$G$200, "")) -> 4 | C16: =IF($A16="","", _xlfn.XLOOKUP($A16, Zaposleni!$B$2:$B$200, Zaposleni!$H$2:$H$200, "")) -> 20 | D16: =MIN(B16,$E$2) -> 4 | E16: =SUMIFS(Odsustva!$F$2:$F$500,Odsustva!$B$2:$B$500,$A16,Odsustva!$G$2:$G$500,$B$1,Odsustva!$E$2:$E$500,"<="&$E$1,Odsustva!$K$2:$K$500,"DA",Odsustva!$J$2:$J$500,"Odobreno")+SUMIFS(Odsustva!$F$2:$F$500,Odsustva!$B$2:$B$500,$A16,Odsustva!$G$2:$G$500,$B$1,Odsustva!$E$2:$E$500,"<="&$E$1,Odsustva!$K$2:$K$500,"DA",Odsustva!$J$2:$J$500,"Evidentirano") -> 0 | F16: =MAX(0,D16-E16) -> 4 | G16: =IF($B$2>$E$1,F16,0) -> 0 | H16: =C16+IF($B$2<=$E$1,F16,0) -> 24 | I16: =SUMIFS(Odsustva!$F$2:$F$500,Odsustva!$B$2:$B$500,$A16,Odsustva!$G$2:$G$500,$B$1,Odsustva!$E$2:$E$500,"<="&$B$2,Odsustva!$K$2:$K$500,"DA",Odsustva!$J$2:$J$500,"Odobreno")+SUMIFS(Odsustva!$F$2:$F$500,Odsustva!$B$2:$B$500,$A16,Odsustva!$G$2:$G$500,$B$1,Odsustva!$E$2:$E$500,"<="&$B$2,Odsustva!$K$2:$K$500,"DA",Odsustva!$J$2:$J$500,"Evidentirano") -> 0 | J16: =SUMIFS(Odsustva!$F$2:$F$500,Odsustva!$B$2:$B$500,$A16,Odsustva!$G$2:$G$500,$B$1,Odsustva!$D$2:$D$500,">"&$B$2,Odsustva!$K$2:$K$500,"DA",Odsustva!$J$2:$J$500,"Planirano")+SUMIFS(Odsustva!$F$2:$F$500,Odsustva!$B$2:$B$500,$A16,Odsustva!$G$2:$G$500,$B$1,Odsustva!$D$2:$D$500,">"&$B$2,Odsustva!$K$2:$K$500,"DA",Odsustva!$J$2:$J$500,"Odobreno") -> 0 | K16: =H16-I16 -> 24 | L16: =K16-J16 -> 24
A17: Ružica Pantović | B17: =IF($A17="","", _xlfn.XLOOKUP($A17, Zaposleni!$B$2:$B$200, Zaposleni!$G$2:$G$200, "")) -> 16 | C17: =IF($A17="","", _xlfn.XLOOKUP($A17, Zaposleni!$B$2:$B$200, Zaposleni!$H$2:$H$200, "")) -> 20 | D17: =MIN(B17,$E$2) -> 16 | E17: =SUMIFS(Odsustva!$F$2:$F$500,Odsustva!$B$2:$B$500,$A17,Odsustva!$G$2:$G$500,$B$1,Odsustva!$E$2:$E$500,"<="&$E$1,Odsustva!$K$2:$K$500,"DA",Odsustva!$J$2:$J$500,"Odobreno")+SUMIFS(Odsustva!$F$2:$F$500,Odsustva!$B$2:$B$500,$A17,Odsustva!$G$2:$G$500,$B$1,Odsustva!$E$2:$E$500,"<="&$E$1,Odsustva!$K$2:$K$500,"DA",Odsustva!$J$2:$J$500,"Evidentirano") -> 0 | F17: =MAX(0,D17-E17) -> 16 | G17: =IF($B$2>$E$1,F17,0) -> 0 | H17: =C17+IF($B$2<=$E$1,F17,0) -> 36 | I17: =SUMIFS(Odsustva!$F$2:$F$500,Odsustva!$B$2:$B$500,$A17,Odsustva!$G$2:$G$500,$B$1,Odsustva!$E$2:$E$500,"<="&$B$2,Odsustva!$K$2:$K$500,"DA",Odsustva!$J$2:$J$500,"Odobreno")+SUMIFS(Odsustva!$F$2:$F$500,Odsustva!$B$2:$B$500,$A17,Odsustva!$G$2:$G$500,$B$1,Odsustva!$E$2:$E$500,"<="&$B$2,Odsustva!$K$2:$K$500,"DA",Odsustva!$J$2:$J$500,"Evidentirano") -> 0 | J17: =SUMIFS(Odsustva!$F$2:$F$500,Odsustva!$B$2:$B$500,$A17,Odsustva!$G$2:$G$500,$B$1,Odsustva!$D$2:$D$500,">"&$B$2,Odsustva!$K$2:$K$500,"DA",Odsustva!$J$2:$J$500,"Planirano")+SUMIFS(Odsustva!$F$2:$F$500,Odsustva!$B$2:$B$500,$A17,Odsustva!$G$2:$G$500,$B$1,Odsustva!$D$2:$D$500,">"&$B$2,Odsustva!$K$2:$K$500,"DA",Odsustva!$J$2:$J$500,"Odobreno") -> 0 | K17: =H17-I17 -> 36 | L17: =K17-J17 -> 36
... A21: Uroš Velinovski | B21: =IF($A21="","", _xlfn.XLOOKUP($A21, Zaposleni!$B$2:$B$200, Zaposleni!$G$2:$G$200, "")) -> 14 | C21: =IF($A21="","", _xlfn.XLOOKUP($A21, Zaposleni!$B$2:$B$200, Zaposleni!$H$2:$H$200, "")) -> 20 | D21: =MIN(B21,$E$2) -> 14 | E21: =SUMIFS(Odsustva!$F$2:$F$500,Odsustva!$B$2:$B$500,$A21,Odsustva!$G$2:$G$500,$B$1,Odsustva!$E$2:$E$500,"<="&$E$1,Odsustva!$K$2:$K$500,"DA",Odsustva!$J$2:$J$500,"Odobreno")+SUMIFS(Odsustva!$F$2:$F$500,Odsustva!$B$2:$B$500,$A21,Odsustva!$G$2:$G$500,$B$1,Odsustva!$E$2:$E$500,"<="&$E$1,Odsustva!$K$2:$K$500,"DA",Odsustva!$J$2:$J$500,"Evidentirano") -> 2 | F21: =MAX(0,D21-E21) -> 12 | G21: =IF($B$2>$E$1,F21,0) -> 0 | H21: =C21+IF($B$2<=$E$1,F21,0) -> 32 | I21: =SUMIFS(Odsustva!$F$2:$F$500,Odsustva!$B$2:$B$500,$A21,Odsustva!$G$2:$G$500,$B$1,Odsustva!$E$2:$E$500,"<="&$B$2,Odsustva!$K$2:$K$500,"DA",Odsustva!$J$2:$J$500,"Odobreno")+SUMIFS(Odsustva!$F$2:$F$500,Odsustva!$B$2:$B$500,$A21,Odsustva!$G$2:$G$500,$B$1,Odsustva!$E$2:$E$500,"<="&$B$2,Odsustva!$K$2:$K$500,"DA",Odsustva!$J$2:$J$500,"Evidentirano") -> 2 | J21: =SUMIFS(Odsustva!$F$2:$F$500,Odsustva!$B$2:$B$500,$A21,Odsustva!$G$2:$G$500,$B$1,Odsustva!$D$2:$D$500,">"&$B$2,Odsustva!$K$2:$K$500,"DA",Odsustva!$J$2:$J$500,"Planirano")+SUMIFS(Odsustva!$F$2:$F$500,Odsustva!$B$2:$B$500,$A21,Odsustva!$G$2:$G$500,$B$1,Odsustva!$D$2:$D$500,">"&$B$2,Odsustva!$K$2:$K$500,"DA",Odsustva!$J$2:$J$500,"Odobreno") -> 0 | K21: =H21-I21 -> 30 | L21: =K21-J21 -> 30
C22: =IF($A22="","", _xlfn.XLOOKUP($A22, Zaposleni!$B$2:$B$200, Zaposleni!$H$2:$H$200, ""))
